Workbook

Sheet Flux de Trésorerie
A2: TABLEAU DES FLUX DE TRÉSORERIE — Méthode Indirecte
A3: PCG français · Exercice 2026 · Comparatif N / N-1
B5: LIBELLÉ | C5: Jan | D5: Fév | E5: Mar | F5: Avr | G5: Mai | H5: Jun | I5: Jul | J5: Aoû | K5: Sep | L5: Oct | M5: Nov | N5: Déc | O5: TOTAL 2026 | P5: N-1 Réel
A6: I. FLUX DE TRÉSORERIE D'EXPLOITATION
B7: Résultat de l'exercice (point de départ) | O7: =SUM(C7:N7) -> 0
A8: + Retraitements non-cash (charges sans sortie de trésorerie)
B9: Dotations aux amortissements et provisions | O9: =SUM(C9:N9) -> 0
B10: Reprises sur amortissements et provisions | O10: =SUM(C10:N10) -> 0
B11: Pertes de valeur (dépréciations) | O11: =SUM(C11:N11) -> 0
B12: Plus ou moins-values de cession d'actifs | O12: =SUM(C12:N12) -> 0
B13: Quote-part des subventions d'exploitation virées | O13: =SUM(C13:N13) -> 0
B14: Autres retraitements non-cash | O14: =SUM(C14:N14) -> 0
A15: ± Variation du besoin en fonds de roulement (BFR)
B16: Variation des stocks (+ diminution / - augmentation) | O16: =SUM(C16:N16) -> 0
B17: Variation des créances clients (DSO) | O17: =SUM(C17:N17) -> 0
B18: Variation des dettes fournisseurs (DPO) | O18: =SUM(C18:N18) -> 0
B19: Variation des autres créances d'exploitation | O19: =SUM(C19:N19) -> 0
B20: Variation des autres dettes d'exploitation | O20: =SUM(C20:N20) -> 0
B21: Variation des dettes fiscales et sociales | O21: =SUM(C21:N21) -> 0
B22: FLUX NET D'EXPLOITATION (A) | C22: =C7+C9+C10+C11+C12+C13+C14+C16+C17+C18+C19+C20+C21 -> 0 | D22: =D7+D9+D10+D11+D12+D13+D14+D16+D17+D18+D19+D20+D21 -> 0 | E22: =E7+E9+E10+E11+E12+E13+E14+E16+E17+E18+E19+E20+E21 -> 0 | F22: =F7+F9+F10+F11+F12+F13+F14+F16+F17+F18+F19+F20+F21 -> 0 | G22: =G7+G9+G10+G11+G12+G13+G14+G16+G17+G18+G19+G20+G21 -> 0 | H22: =H7+H9+H10+H11+H12+H13+H14+H16+H17+H18+H19+H20+H21 -> 0 | I22: =I7+I9+I10+I11+I12+I13+I14+I16+I17+I18+I19+I20+I21 -> 0 | J22: =J7+J9+J10+J11+J12+J13+J14+J16+J17+J18+J19+J20+J21 -> 0 | ... O22: =O7+O9+O10+O11+O12+O13+O14+O16+O17+O18+O19+O20+O21 -> 0
A24: II. FLUX DE TRÉSORERIE D'INVESTISSEMENT
A25: - Acquisitions d'actifs (sorties)
B26: Acquisitions d'immobilisations incorporelles | O26: =SUM(C26:N26) -> 0
B27: Acquisitions d'immobilisations corporelles (Capex) | O27: =SUM(C27:N27) -> 0
B28: Acquisitions d'immobilisations financières | O28: =SUM(C28:N28) -> 0
B29: Acquisitions de titres de participation | O29: =SUM(C29:N29) -> 0
B30: Prêts accordés | O30: =SUM(C30:N30) -> 0
A31: + Cessions d'actifs (entrées)
B32: Cessions d'immobilisations incorporelles | O32: =SUM(C32:N32) -> 0
B33: Cessions d'immobilisations corporelles | O33: =SUM(C33:N33) -> 0
B34: Cessions de titres de participation | O34: =SUM(C34:N34) -> 0
B35: Remboursements de prêts accordés | O35: =SUM(C35:N35) -> 0
B36: Subventions d'investissement reçues | O36: =SUM(C36:N36) -> 0
B37: FLUX NET D'INVESTISSEMENT (B) | C37: =C26+C27+C28+C29+C30+C32+C33+C34+C35+C36 -> 0 | D37: =D26+D27+D28+D29+D30+D32+D33+D34+D35+D36 -> 0 | E37: =E26+E27+E28+E29+E30+E32+E33+E34+E35+E36 -> 0 | F37: =F26+F27+F28+F29+F30+F32+F33+F34+F35+F36 -> 0 | G37: =G26+G27+G28+G29+G30+G32+G33+G34+G35+G36 -> 0 | H37: =H26+H27+H28+H29+H30+H32+H33+H34+H35+H36 -> 0 | I37: =I26+I27+I28+I29+I30+I32+I33+I34+I35+I36 -> 0 | J37: =J26+J27+J28+J29+J30+J32+J33+J34+J35+J36 -> 0 | ... O37: =O26+O27+O28+O29+O30+O32+O33+O34+O35+O36 -> 0
A39: III. FLUX DE TRÉSORERIE DE FINANCEMENT
A40: + Apports et emprunts (entrées)
B41: Augmentations de capital en numéraire | O41: =SUM(C41:N41) -> 0
B42: Nouveaux emprunts bancaires | O42: =SUM(C42:N42) -> 0
B43: Émissions d'obligations | O43: =SUM(C43:N43) -> 0
B44: Subventions financières reçues | O44: =SUM(C44:N44) -> 0
...

Sheet Hypotheses
A2: HYPOTHÈSES & SCÉNARIOS — Tableau de Flux de Trésorerie 2026
A3: Modifiez les hypothèses ici — les flux se recalculent automatiquement
A5: EXPLOITATION
B6: PARAMÈTRE | C6: PESSIMISTE | D6: BASE | E6: OPTIMISTE | F6: COMMENTAIRE
B7: Croissance chiffre d'affaires | C7: 0.05 | D7: 0.15 | E7: 0.3 | F7: vs N-1
B8: Taux de marge brute | C8: 0.35 | D8: 0.45 | E8: 0.55 | F8: CA - Achats / CA
B9: DSO — délai clients (jours) | C9: 75 | D9: 60 | E9: 45 | F9: Jours de CA
B10: DPO — délai fournisseurs (jours) | C10: 30 | D10: 45 | E10: 60 | F10: Jours d'achats
B11: DIO — délai de stockage (jours) | C11: 45 | D11: 30 | E11: 15 | F11: Jours de CA
B12: Taux de charges fixes / CA | C12: 0.28 | D12: 0.25 | E12: 0.22 | F12: Hors amort.
A14: INVESTISSEMENT
B15: PARAMÈTRE | C15: PESSIMISTE | D15: BASE | E15: OPTIMISTE | F15: COMMENTAIRE
B16: Capex annuel | C16: 30000 | D16: 50000 | E16: 80000 | F16: Immobilisations corp.
B17: Durée amortissement moyenne (ans) | C17: 5 | D17: 5 | E17: 7
B18: Cessions d'actifs prévues | C18: 0 | D18: 0 | E18: 15000
A20: FINANCEMENT
B21: PARAMÈTRE | C21: PESSIMISTE | D21: BASE | E21: OPTIMISTE | F21: COMMENTAIRE
B22: Nouveaux emprunts | C22: 0 | D22: 50000 | E22: 100000 | F22: Lignes bancaires
B23: Remboursements annuels d'emprunts | C23: 24000 | D23: 36000 | E23: 48000
B24: Taux d'intérêt moyen | C24: 0.045 | D24: 0.04 | E24: 0.035
B25: Dividendes versés | C25: 0 | D25: 0 | E25: 20000 | F25: Si résultat suffisant
A27: SCÉNARIO ACTIF — Sélectionnez dans la liste déroulante :
B28: Scénario sélectionné : | C28: BASE | D28: ↑ Choisir le scénario
A30: Texte bleu = saisie / hypothèse modifiable | Plage de scénarios : colonne C (Pessimiste) · D (Base) · E (Optimiste)

Sheet Tableau de Bord
A2: TABLEAU DE BORD TRÉSORERIE — Synthèse & KPIs 2026
A3: Données liées automatiquement depuis la feuille 'Flux de Trésorerie'
B6: Flux exploitation YTD | C6: Flux investissement YTD | D6: Flux financement YTD | E6: Variation nette
B7: ='Flux de Trésorerie'!O22 -> 0 | C7: ='Flux de Trésorerie'!O37 -> 0 | D7: ='Flux de Trésorerie'!O53 -> 0 | E7: ='Flux de Trésorerie'!O55 -> 0
A10: SUIVI MENSUEL — Flux net par mois et trésorerie cumulée
B11: MOIS | C11: Flux exploit. | D11: Flux invest. | E11: Flux financ. | F11: Variation nette | G11: Tréso clôture | H11: vs Mois préc.
B12: Jan | C12: ='Flux de Trésorerie'!C22 -> 0 | D12: ='Flux de Trésorerie'!C37 -> 0 | E12: ='Flux de Trésorerie'!C53 -> 0 | F12: ='Flux de Trésorerie'!C55 -> 0 | G12: ='Flux de Trésorerie'!C59 -> 0
B13: Fév | C13: ='Flux de Trésorerie'!D22 -> 0 | D13: ='Flux de Trésorerie'!D37 -> 0 | E13: ='Flux de Trésorerie'!D53 -> 0 | F13: ='Flux de Trésorerie'!D55 -> 0 | G13: ='Flux de Trésorerie'!D59 -> 0 | H13: =G13-G12 -> 0
B14: Mar | C14: ='Flux de Trésorerie'!E22 -> 0 | D14: ='Flux de Trésorerie'!E37 -> 0 | E14: ='Flux de Trésorerie'!E53 -> 0 | F14: ='Flux de Trésorerie'!E55 -> 0 | G14: ='Flux de Trésorerie'!E59 -> 0 | H14: =G14-G13 -> 0
B15: Avr | C15: ='Flux de Trésorerie'!F22 -> 0 | D15: ='Flux de Trésorerie'!F37 -> 0 | E15: ='Flux de Trésorerie'!F53 -> 0 | F15: ='Flux de Trésorerie'!F55 -> 0 | G15: ='Flux de Trésorerie'!F59 -> 0 | H15: =G15-G14 -> 0
B16: Mai | C16: ='Flux de Trésorerie'!G22 -> 0 | D16: ='Flux de Trésorerie'!G37 -> 0 | E16: ='Flux de Trésorerie'!G53 -> 0 | F16: ='Flux de Trésorerie'!G55 -> 0 | G16: ='Flux de Trésorerie'!G59 -> 0 | H16: =G16-G15 -> 0
B17: Jun | C17: ='Flux de Trésorerie'!H22 -> 0 | D17: ='Flux de Trésorerie'!H37 -> 0 | E17: ='Flux de Trésorerie'!H53 -> 0 | F17: ='Flux de Trésorerie'!H55 -> 0 | G17: ='Flux de Trésorerie'!H59 -> 0 | H17: =G17-G16 -> 0
B18: Jul | C18: ='Flux de Trésorerie'!I22 -> 0 | D18: ='Flux de Trésorerie'!I37 -> 0 | E18: ='Flux de Trésorerie'!I53 -> 0 | F18: ='Flux de Trésorerie'!I55 -> 0 | G18: ='Flux de Trésorerie'!I59 -> 0 | H18: =G18-G17 -> 0
B19: Aoû | C19: ='Flux de Trésorerie'!J22 -> 0 | D19: ='Flux de Trésorerie'!J37 -> 0 | E19: ='Flux de Trésorerie'!J53 -> 0 | F19: ='Flux de Trésorerie'!J55 -> 0 | G19: ='Flux de Trésorerie'!J59 -> 0 | H19: =G19-G18 -> 0
B20: Sep | C20: ='Flux de Trésorerie'!K22 -> 0 | D20: ='Flux de Trésorerie'!K37 -> 0 | E20: ='Flux de Trésorerie'!K53 -> 0 | F20: ='Flux de Trésorerie'!K55 -> 0 | G20: ='Flux de Trésorerie'!K59 -> 0 | H20: =G20-G19 -> 0
B21: Oct | C21: ='Flux de Trésorerie'!L22 -> 0 | D21: ='Flux de Trésorerie'!L37 -> 0 | E21: ='Flux de Trésorerie'!L53 -> 0 | F21: ='Flux de Trésorerie'!L55 -> 0 | G21: ='Flux de Trésorerie'!L59 -> 0 | H21: =G21-G20 -> 0
B22: Nov | C22: ='Flux de Trésorerie'!M22 -> 0 | D22: ='Flux de Trésorerie'!M37 -> 0 | E22: ='Flux de Trésorerie'!M53 -> 0 | F22: ='Flux de Trésorerie'!M55 -> 0 | G22: ='Flux de Trésorerie'!M59 -> 0 | H22: =G22-G21 -> 0
B23: Déc | C23: ='Flux de Trésorerie'!N22 -> 0 | D23: ='Flux de Trésorerie'!N37 -> 0 | E23: ='Flux de Trésorerie'!N53 -> 0 | F23: ='Flux de Trésorerie'!N55 -> 0 | G23: ='Flux de Trésorerie'!N59 -> 0 | H23: =G23-G22 -> 0
A25: Texte vert = données liées depuis 'Flux de Trésorerie' | Tréso rouge = solde négatif = ALERTE | Tréso vert = solde > 50 000 €
